*** Scanning
Traceback (most recent call last):
  File "./zmap_s3_poc.py", line 184, in <module>
    zmap_scan_obj.run()
  File "./zmap_s3_poc.py", line 116, in run
    with open(self.cmdline_out_file_path, 'wt') as cmdline_out_f:
IOError: [Errno 2] No such file or directory: u'/tmp/zmap_output/2018-02-02T13:38:08.013738.0.0.0.0_0.udp.53.cmdline'

DNS failed to scan! Retrying DNS scan at 13:38:07 

*** Scanning
Traceback (most recent call last):
  File "./zmap_s3_poc.py", line 184, in <module>
    zmap_scan_obj.run()
  File "./zmap_s3_poc.py", line 116, in run
    with open(self.cmdline_out_file_path, 'wt') as cmdline_out_f:
IOError: [Errno 2] No such file or directory: u'/tmp/zmap_output/2018-02-02T13:38:08.027562.0.0.0.0_0.udp.53.cmdline'

DNS failed to scan! Please check your configuration 

